<?xml version="1.0"?>
<robot name="lio" xmlns:xacro="http://tixiaoshan.github.io/">
  <xacro:property name="PI" value="3.1415926535897931" />

  <link name="odom"></link>
  <link name="base_link"></link>

  <joint name="odom_joint" type="continuous">
    <origin xyz="0.0 0.0 0.0" rpy="0.0 0.0 0.0"/>
    <parent link="odom"/>
    <child link="base_link"/>
  </joint>

  <link name="lidar_link"></link>
  <joint name="lidar_joint" type="fixed">
    <parent link="base_link" />
    <child link="lidar_link" />
    <origin xyz="0 0 0" rpy="0 0 0" />
  </joint>

  <link name="velodyne"></link>
  <joint name="velodyne_joint" type="fixed">
    <parent link="base_link" />
    <child link="velodyne" />
    <origin xyz="0 0 0" rpy="0 0 0" />
  </joint>

  <link name="laser_data_frame"></link>
  <joint name="laser_data_frame_joint" type="fixed">
    <parent link="base_link" />
    <child link="laser_data_frame" />
    <origin xyz="0 0 0" rpy="0 0 0" />
  </joint>

  <link name="imu_link"> </link>
  <joint name="imu_joint" type="fixed">
    <parent link="base_link" />
    <child link="imu_link" />
    <origin xyz="0 0 0" rpy="0 0 0" />
  </joint>

  <link name="laser_sensor_frame"> </link>
  <joint name="laser_joint" type="fixed">
    <parent link="imu_link" />
    <child link="laser_sensor_frame" />
    <origin xyz="0 0 0" rpy="0 0 0" />
  </joint>

  <link name="navsat_link"> </link>
  <joint name="navsat_joint" type="fixed">
    <parent link="base_link" />
    <child link="navsat_link" />
    <origin xyz="0 0 0" rpy="0 0 0" />
  </joint>

</robot>
